Workbook

Sheet Cover
B3: WBA / SYCAMORE PARTNERS
B4: Independent Valuation Analysis
B5: 45717
B6: Kenny Manning
B10: DEAL OVERVIEW
B11: Target | C11: Walgreens Boots Alliance, Inc. (WBA)
B12: Acquirer | C12: Sycamore Partners
B13: Announcement | C13: March 6, 2025
B14: Close | C14: August 28, 2025
B15: Cash Consideration | C15: $11.45 per share
B16: Contingent Value Right (DAP) | C16: Up to $3.00/share — VillageMD monetization
B17: Total Consideration | C17: Up to $14.45 per share
B18: Total Transaction Value | C18: Up to $23.7 billion
B19: Reference Price | C19: $8.85 (Dec 9, 2024 close)
B20: Cash Premium | C20: 29% to reference price
B21: Total Premium (incl. DAP) | C21: Up to 63% to reference price
B22: Financing Condition | C22: None — fully committed at signing
B23: Post-Close Structure | C23: 5 standalone entities: Walgreens, Boots, Shields, CareCentrix, VillageMD
B25: TAB GUIDE
B26: 1 — Cover | C26: This page — deal overview and tab navigation guide
B27: 2 — Assumptions | C27: Central input hub — all key model drivers (edit here)
B28: 3 — WBA Financials | C28: Historical income statement & cash flow FY2021–FY2024
B29: 4 — DCF Model | C29: 5-year FCF projections, WACC build, terminal value, sensitivity tables
B30: 5 — Comps | C30: Trading comparable companies — peer multiples → implied WBA price
B31: 6 — Precedents | C31: Precedent transaction multiples → implied WBA price range
B32: 7 — Football Field | C32: Summary chart — valuation ranges vs. deal price ($11.45 / $14.45)
B33: 8 — Deal vs. Model | C33: Side-by-side deal price vs. model outputs + analytical conclusion

Sheet Assumptions
B2: ASSUMPTIONS — Central Model Input Hub
B4: All monetary values in $ billions unless otherwise noted.
B6: DCF PROJECTION ASSUMPTIONS
B7: FY2025E Revenue Growth | C7: 0.02
B8: FY2026E Revenue Growth | C8: 0.015
B9: FY2027E Revenue Growth | C9: 0.01
B10: FY2028E Revenue Growth | C10: 0.01
B11: FY2029E Revenue Growth | C11: 0.01
B12: FY2025E Adj. EBITDA Margin | C12: 0.0265
B13: FY2026E Adj. EBITDA Margin | C13: 0.0255
B14: FY2027E Adj. EBITDA Margin | C14: 0.0245
B15: FY2028E Adj. EBITDA Margin | C15: 0.024
B16: FY2029E Adj. EBITDA Margin | C16: 0.0235
B17: FY2025E D&A | C17: 1.75
B18: FY2026E D&A | C18: 1.7
... B28: Tax Rate | C28: 0.25
B30: WACC BUILD
B31: Risk-Free Rate (10-yr UST, March 2025) | C31: 0.043
B32: Equity Risk Premium (Damodaran 2025) | C32: 0.055
B33: Levered Beta | C33: 0.85
B34: Cost of Equity | C34: =C31+C33*C32 -> 0.08975
B35: Pre-Tax Cost of Debt | C35: 0.065
B36: After-Tax Cost of Debt | C36: =C35*(1-C28) -> 0.04875
B37: Debt Weight | C37: 0.52
B38: Equity Weight | C38: =1-C37 -> 0.48
B39: WACC | C39: =C37*C36+C38*C34 -> 0.06843
B41: TERMINAL VALUE
B42: Exit EV/EBITDA Multiple (base case) | C42: 6.5
B43: Terminal Growth Rate — Gordon Growth (base case) | C43: 0.01
B45: CAPITAL STRUCTURE (as of deal announcement, March 2025)
B46: Shares Outstanding (billions) | C46: 0.862
B47: Net Debt | C47: 10.1
B48: Minority Interests | C48: 0.3
B50: COMPS & PRECEDENTS — Applied Multiple Ranges
B51: Comps — Low EV/EBITDA Multiple | C51: 5
B52: Comps — Mid EV/EBITDA Multiple | C52: 6.5
B53: Comps — High EV/EBITDA Multiple | C53: 8.5
B54: Precedents — Low EV/EBITDA Multiple | C54: 5.5
B55: Precedents — Mid EV/EBITDA Multiple | C55: 8
B56: Precedents — High EV/EBITDA Multiple | C56: 10.5

Sheet WBA Financials
B2: WBA HISTORICAL FINANCIALS — FY2021–FY2024 (fiscal year ends Aug 31)
B4: All monetary values in $ billions unless otherwise noted.
B6: Income Statement
B7: Metric | C7: FY2021A | D7: FY2022A | E7: FY2023A | F7: FY2024A
B8: Revenue | C8: 132.5 | D8: 132.7 | E8: 139.1 | F8: 147.7
B9: Revenue Growth (YoY) | C9: — | D9: =D8/C8-1 -> 0.001509434 | E9: =E8/D8-1 -> 0.048229088 | F9: =F8/E8-1 -> 0.061826024
B10: Adj. EBITDA | C10: 5.6 | D10: 5.1 | E10: 4.5 | F10: 3.9
B11: EBITDA Margin | C11: =C10/C8 -> 0.042264151 | D11: =D10/D8 -> 0.038432555 | E11: =E10/E8 -> 0.032350827 | F11: =F10/F8 -> 0.026404875
B12: D&A | C12: 1.7 | D12: 1.7 | E12: 1.8 | F12: 1.8
B13: Adj. EBIT | C13: =C10-C12 -> 3.9 | D13: =D10-D12 -> 3.4 | E13: =E10-E12 -> 2.7 | F13: =F10-F12 -> 2.1
B14: EBIT Margin | C14: =C13/C8 -> 0.029433962 | D14: =D13/D8 -> 0.025621703 | E14: =E13/E8 -> 0.019410496 | F14: =F13/F8 -> 0.014218009
B16: Capital Expenditures & Free Cash Flow
B17: Metric | C17: FY2021A | D17: FY2022A | E17: FY2023A | F17: FY2024A
B18: Capital Expenditures | C18: 1.5 | D18: 1.7 | E18: 1.3 | F18: 1.1
B19: CapEx as % of Revenue | C19: =C18/C8 -> 0.011320755 | D19: =D18/D8 -> 0.012810852 | E19: =E18/E8 -> 0.0093457944 | F19: =F18/F8 -> 0.0074475288
B20: Approx. Free Cash Flow* | C20: =C10-C18 -> 4.1 | D20: =D10-D18 -> 3.4 | E20: =E10-E18 -> 3.2 | F20: =F10-F18 -> 2.8
B21: FCF Margin | C21: =C20/C8 -> 0.030943396 | D21: =D20/D8 -> 0.025621703 | E21: =E20/E8 -> 0.023005032 | F21: =F20/F8 -> 0.018957346
B23: KEY TRENDS
B24: ▪ Revenue grew 11.5% cumulatively FY2021–FY2024, driven by pharmacy script volume; retail front-end remained pressured.
B25: ▪ Adj. EBITDA declined 30.4% ($5.6B→$3.9B) on pharmacy reimbursement compression and rising SG&A costs.
B26: ▪ EBITDA margin fell ~160bps from 4.2% to 2.6% — structural deterioration, not a temporary cyclical issue.
B27: ▪ CapEx fell from $1.7B (FY2022) to $1.1B (FY2024) as management shifted to capital preservation vs. growth investment.
B29: * Approx. FCF = EBITDA − CapEx; excludes taxes and working capital changes. See DCF Model for unlevered FCF definition. Sources: WBA Annual Reports (10-K) FY2021–FY2024; WBA Earnings Releases.

Sheet DCF Model
B2: DISCOUNTED CASH FLOW MODEL — WBA / Sycamore Partners
B4: All monetary values in $ billions unless otherwise noted.
B6: REVENUE & EBITDA PROJECTIONS
C7: FY2024A | D7: FY2025E | E7: FY2026E | F7: FY2027E | G7: FY2028E | H7: FY2029E
B8: Revenue | C8: 147.7 | D8: =C8*(1+D9) -> 150.654 | E8: =D8*(1+E9) -> 152.91381 | F8: =E8*(1+F9) -> 154.44295 | G8: =F8*(1+G9) -> 155.98738 | H8: =G8*(1+H9) -> 157.54725
B9: Revenue Growth (YoY) | C9: — | D9: =Assumptions!C7 -> 0.02 | E9: =Assumptions!C8 -> 0.015 | F9: =Assumptions!C9 -> 0.01 | G9: =Assumptions!C10 -> 0.01 | H9: =Assumptions!C11 -> 0.01
B10: Adj. EBITDA | C10: 3.9 | D10: =D8*D11 -> 3.992331 | E10: =E8*E11 -> 3.8993022 | F10: =F8*F11 -> 3.7838522 | G10: =G8*G11 -> 3.7436971 | H10: =H8*H11 -> 3.7023604
B11: EBITDA Margin | C11: 0.026404875 | D11: =Assumptions!C12 -> 0.0265 | E11: =Assumptions!C13 -> 0.0255 | F11: =Assumptions!C14 -> 0.0245 | G11: =Assumptions!C15 -> 0.024 | H11: =Assumptions!C16 -> 0.0235
B12: D&A | C12: 1.8 | D12: =Assumptions!C17 -> 1.75 | E12: =Assumptions!C18 -> 1.7 | F12: =Assumptions!C19 -> 1.65 | G12: =Assumptions!C20 -> 1.6 | H12: =Assumptions!C21 -> 1.55
B13: Adj. EBIT | C13: 2.1 | D13: =D10-D12 -> 2.242331 | E13: =E10-E12 -> 2.1993022 | F13: =F10-F12 -> 2.1338522 | G13: =G10-G12 -> 2.1436971 | H13: =H10-H12 -> 2.1523604
B14: Tax Rate | C14: 0.25 | D14: =Assumptions!C28 -> 0.25 | E14: =Assumptions!C28 -> 0.25 | F14: =Assumptions!C28 -> 0.25 | G14: =Assumptions!C28 -> 0.25 | H14: =Assumptions!C28 -> 0.25
B15: NOPLAT | C15: 1.575 | D15: =D13*(1-D14) -> 1.6817482 | E15: =E13*(1-E14) -> 1.6494766 | F15: =F13*(1-F14) -> 1.6003892 | G15: =G13*(1-G14) -> 1.6077728 | H15: =H13*(1-H14) -> 1.6142703
B16: (+) D&A | C16: 1.8 | D16: =D12 -> 1.75 | E16: =E12 -> 1.7 | F16: =F12 -> 1.65 | G16: =G12 -> 1.6 | H16: =H12 -> 1.55
B17: (−) CapEx | C17: -1.1 | D17: =-Assumptions!C22 -> -1.1 | E17: =-Assumptions!C23 -> -1.05 | F17: =-Assumptions!C24 -> -1 | G17: =-Assumptions!C25 -> -0.95 | H17: =-Assumptions!C26 -> -0.9
B18: (−) Change in Working Capital | C18: — | D18: =Assumptions!C27 -> -0.2 | E18: =Assumptions!C27 -> -0.2 | F18: =Assumptions!C27 -> -0.2 | G18: =Assumptions!C27 -> -0.2 | H18: =Assumptions!C27 -> -0.2
B19: Unlevered Free Cash Flow | C19: — | D19: =D15+D16+D17+D18 -> 2.1317482 | E19: =E15+E16+E17+E18 -> 2.0994766 | F19: =F15+F16+F17+F18 -> 2.0503892 | G19: =G15+G16+G17+G18 -> 2.0577728 | H19: =H15+H16+H17+H18 -> 2.0642703
B21: WACC BUILD
B22: Risk-Free Rate (10-yr UST) | C22: =Assumptions!C31 -> 0.043
B23: Equity Risk Premium | C23: =Assumptions!C32 -> 0.055
B24: Levered Beta | C24: 0.85
B25: Cost of Equity | C25: =C22+C24*C23 -> 0.08975
B26: Pre-Tax Cost of Debt | C26: 0.065
B27: After-Tax Cost of Debt | C27: =C26*(1-Assumptions!C28) -> 0.04875
B28: Debt Weight | C28: 0.52
B29: Equity Weight | C29: =1-C28 -> 0.48
B30: WACC | C30: =C28*C27+C29*C25 -> 0.06843
B32: TERMINAL VALUE & IMPLIED SHARE PRICE
B34: METHOD 1 — EXIT MULTIPLE
B35: FY2029E Adj. EBITDA | C35: =H10 -> 3.7023604
B36: Exit EV/EBITDA Multiple (base case) | C36: =Assumptions!C42 -> 6.5
B37: Terminal Value | C37: =C35*C36 -> 24.065343
B38: PV of Terminal Value | C38: =C37/POWER(1+C30,5) -> 17.284693
B39: PV of FCFs | C39: =D19/POWER(1+C30,1)+E19/POWER(1+C30,2)+F19/POWER(1+C30,3)+G19/POWER(1+C30,4)+H19/POWER(1+C30,5) -> 8.5772449
B40: Enterprise Value | C40: =C38+C39 -> 25.861938
B41: (−) Net Debt | C41: =Assumptions!C47 -> 10.1
B42: (−) Minority Interests | C42: =Assumptions!C48 -> 0.3
B43: Implied Equity Value | C43: =C40-C41-C42 -> 15.461938
B44: Shares Outstanding (billions) | C44: =Assumptions!C46 -> 0.862
B45: IMPLIED SHARE PRICE — EXIT MULTIPLE | C45: =C43/C44 -> 17.937283
B47: METHOD 2 — GORDON GROWTH
...

Sheet Comps
B2: COMPARABLE COMPANIES ANALYSIS (circa March 2025)
B4: All monetary values in $ billions unless otherwise noted.
B6: Company | C6: Ticker | D6: LTM Revenue | E6: LTM EBITDA | F6: Enterprise Value | G6: EV/Revenue | H6: EV/EBITDA
B7: CVS Health | C7: CVS | D7: 372.8 | E7: 17.7 | F7: 110 | G7: 0.3 | H7: 6.2
B8: McKesson | C8: MCK | D8: 309 | E8: 6.7 | F8: 79.5 | G8: 0.26 | H8: 11.9
B9: Cencora | C9: COR | D9: 293.8 | E9: 5.1 | F9: 55 | G9: 0.19 | H9: 10.8
B10: Cardinal Health | C10: CAH | D10: 222.4 | E10: 2.9 | F10: 25.5 | G10: 0.11 | H10: 8.8
B11: Rite Aid* | C11: RAD | D11: 21.8 | E11: 0.5 | F11: 2.5 | G11: 0.11 | H11: 5
B12: Min (excl. Rite Aid) | G12: 0.11 | H12: 6.2
B13: 25th Percentile (excl. Rite Aid) | G13: 0.17 | H13: 8.1
B14: Median (excl. Rite Aid) | G14: 0.22 | H14: 9.8
B15: Mean (excl. Rite Aid) | G15: 0.21 | H15: 9.4
B16: 75th Percentile (excl. Rite Aid) | G16: 0.27 | H16: 11.1
B17: Max (excl. Rite Aid) | G17: 0.3 | H17: 11.9
B19: * Rite Aid excluded from statistics — in bankruptcy/restructuring; included as a floor reference only. † Applied low multiple of 5.0x reflects a WBA-specific distress discount below the comp-set floor (CVS at 6.2x).
B21: WBA APPLICATION — Implied Share Price from Comps
B22: WBA LTM EBITDA: $3.9B │ Net Debt: $10.1B │ Minorities: $0.3B │ Shares: 862M
B23: Case | C23: EV/EBITDA Applied | D23: Implied EV | E23: Less: Net Debt + Minorities | F23: Implied Equity Value | G23: Shares (billions) | H23: Implied Price ($/sh)
B24: Low — 5.0x | C24: =Assumptions!C51 -> 5 | D24: =C24*'WBA Financials'!F10 -> 19.5 | E24: =Assumptions!C47+Assumptions!C48 -> 10.4 | F24: =D24-E24 -> 9.1 | G24: =Assumptions!C46 -> 0.862 | H24: =F24/G24 -> 10.556845
B25: Mid — 6.5x | C25: =Assumptions!C52 -> 6.5 | D25: =C25*'WBA Financials'!F10 -> 25.35 | E25: =Assumptions!C47+Assumptions!C48 -> 10.4 | F25: =D25-E25 -> 14.95 | G25: =Assumptions!C46 -> 0.862 | H25: =F25/G25 -> 17.343387
B26: High — 8.5x | C26: =Assumptions!C53 -> 8.5 | D26: =C26*'WBA Financials'!F10 -> 33.15 | E26: =Assumptions!C47+Assumptions!C48 -> 10.4 | F26: =D26-E26 -> 22.75 | G26: =Assumptions!C46 -> 0.862 | H26: =F26/G26 -> 26.392111
B28: Sources: FactSet; public filings. Multiples as of March 2025 deal announcement. Peer set reflects pharmacy retail and distribution sector.

Sheet Precedents
B2: PRECEDENT TRANSACTIONS ANALYSIS — Healthcare & Pharmacy Take-Privates
B4: All monetary values in $ billions unless otherwise noted.
B6: Target | C6: Acquirer | D6: Year | E6: Sector | F6: Enterprise Value | G6: LTM Revenue | H6: LTM EBITDA | I6: EV/Revenue | J6: EV/EBITDA
B7: Envision Healthcare | C7: KKR | D7: 2018 | E7: Healthcare Services | F7: 9.9 | G7: 7.8 | H7: 0.82 | I7: 1.27 | J7: 12.1
B8: LifePoint Health | C8: Apollo Global | D8: 2018 | E8: Healthcare | F8: 5.6 | G8: 6.1 | H8: 0.71 | I8: 0.92 | J8: 7.9
B9: PharMerica | C9: KKR | D9: 2018 | E9: Pharmacy Services | F9: 1.4 | G9: 2.1 | H9: 0.18 | I9: 0.67 | J9: 7.8
B10: US Foods (blocked) | C10: Sysco | D10: 2019 | E10: Food Distribution | F10: 8.2 | G10: 24.2 | H10: 0.61 | I10: 0.34 | J10: 13.4
B11: DaVita (ref. only) | C11: Berkshire Hathaway | D11: 2019 | E11: Healthcare Services | F11: 8.9 | G11: 11.4 | H11: 1.95 | I11: 0.78 | J11: 4.6
B12: Change Healthcare | C12: Optum/UnitedHealth | D12: 2022 | E12: Healthcare IT | F12: 13 | G12: 3.3 | H12: 0.89 | I12: 3.94 | J12: 14.6
B13: Magellan Health | C13: Centene | D13: 2022 | E13: Healthcare Services | F13: 2.2 | G13: 7.9 | H13: 0.26 | I13: 0.28 | J13: 8.5
B14: Min (clean set) | J14: 7.8
B15: 25th Percentile (clean set) | J15: 7.9
B16: Median (clean set) | J16: 8.2
B17: Mean (clean set) | J17: 9
B18: 75th Percentile (clean set) | J18: 9.4
B19: Max (clean set) | J19: 12.1
B21: Clean set: Envision, LifePoint, PharMerica, Magellan. Excluded: † not a PE take-private or sector mismatch; ‡ healthcare IT outlier (Change Healthcare, 14.6x) — materially different business model.
B23: WBA APPLICATION — Implied Share Price from Precedents
B24: WBA LTM EBITDA: $3.9B │ Net Debt: $10.1B │ Minorities: $0.3B │ Shares: 862M │ Implied Deal Multiple: ~5.1x (cash) / ~5.8x (total)
B25: Case | C25: EV/EBITDA Applied | D25: Implied EV | E25: Less: Net Debt + Minorities | F25: Implied Equity Value | G25: Shares (billions) | H25: Implied Price ($/sh)
B26: Low — 5.5x | C26: =Assumptions!C54 -> 5.5 | D26: =C26*'WBA Financials'!F10 -> 21.45 | E26: =Assumptions!C47+Assumptions!C48 -> 10.4 | F26: =D26-E26 -> 11.05 | G26: =Assumptions!C46 -> 0.862 | H26: =F26/G26 -> 12.819026
B27: Mid — 8.0x | C27: =Assumptions!C55 -> 8 | D27: =C27*'WBA Financials'!F10 -> 31.2 | E27: =Assumptions!C47+Assumptions!C48 -> 10.4 | F27: =D27-E27 -> 20.8 | G27: =Assumptions!C46 -> 0.862 | H27: =F27/G27 -> 24.12993
B28: High — 10.5x | C28: =Assumptions!C56 -> 10.5 | D28: =C28*'WBA Financials'!F10 -> 40.95 | E28: =Assumptions!C47+Assumptions!C48 -> 10.4 | F28: =D28-E28 -> 30.55 | G28: =Assumptions!C46 -> 0.862 | H28: =F28/G28 -> 35.440835
B30: The deal was priced at ~5.1x LTM EBITDA (cash only) — well below the clean precedents median of ~8.2x, reflecting WBA's distress profile, PE restructuring discount, and healthcare platform uncertainty.
B32: Sources: SEC filings; press releases; public news for each transaction. Figures represent approximate LTM financials at deal announcement.

Sheet Football Field
B2: FOOTBALL FIELD — Implied Valuation Range vs. Deal Price
B5: Methodology | C5: Low ($/sh) | D5: Base Case ($/sh) | E5: High ($/sh)
B6: DCF — Exit Multiple | C6: ='DCF Model'!C66 -> 8.839479 | D6: ='DCF Model'!E61 -> 17.937283 | E6: ='DCF Model'!G62 -> 20.971015
B7: DCF — Gordon Growth | C7: ='DCF Model'!C77 -> 7.9774447 | D7: ='DCF Model'!E72 -> 27.61677 | E7: ='DCF Model'!G73 -> 25.292728
B8: Comparable Companies | C8: =Comps!H24 -> 10.556845 | D8: =Comps!H25 -> 17.343387 | E8: =Comps!H26 -> 26.392111
B9: Precedent Transactions | C9: =Precedents!H26 -> 12.819026 | D9: =Precedents!H27 -> 24.12993 | E9: =Precedents!H28 -> 35.440835
B10: Deal Price — Cash Only | C10: 11.45 | D10: 11.45 | E10: 11.45
B11: Deal Price — Total (incl. DAP) | C11: 14.45 | D11: 14.45 | E11: 14.45
B13: CHART DATA
B14: Methodology (chart labels) | C14: Base (offset) | D14: Range Width | E14: Base Case
B15: DCF — Exit Multiple | C15: =C6 -> 8.839479 | D15: =E6-C6 -> 12.131536 | E15: =D6 -> 17.937283
B16: DCF — Gordon Growth | C16: =C7 -> 7.9774447 | D16: =E7-C7 -> 17.315283 | E16: =D7 -> 27.61677
B17: Comparable Companies | C17: =C8 -> 10.556845 | D17: =E8-C8 -> 15.835267 | E17: =D8 -> 17.343387
B18: Precedent Transactions | C18: =C9 -> 12.819026 | D18: =E9-C9 -> 22.62181 | E18: =D9 -> 24.12993
B19: Deal Price (Cash, $11.45) | C19: =C10 -> 11.45 | D19: =0 -> 0 | E19: =C10 -> 11.45
B20: Deal Price (Total, $14.45) | C20: =C11 -> 14.45 | D20: =0 -> 0 | E20: =C11 -> 14.45
B48: KEY OBSERVATIONS
B49: ▪ DCF — Exit Multiple: Within range ($8.84–$20.97). Base case $17.94/sh at 6.84% WACC / 6.5x exit. Deal at $11.45 is ~36% below base-case intrinsic value, consistent with a PE buyer acquiring at a discount to long-run fair value.
B50: ▪ Comparable Companies: Within range ($10.56–$26.39). Wide range reflects distress discount applied to peer multiples.
B51: ▪ Precedent Transactions: Below range ($12.82–$35.44). Deal priced at ~5.1x EV/EBITDA vs. a comparable healthcare take-private median of ~8.2x, reflecting WBA’s distress and restructuring risk.
B52: ▪ The DAP right (up to $3.00/share) prices VillageMD optionality separately, enabling the $11.45 cash price to reflect core pharmacy value only.
B54: Sources: Model analysis; WBA 10-K FY2024; FactSet consensus; SEC filings for precedent transactions.

Sheet Deal vs. Model
B2: DEAL vs. MODEL — WBA / Sycamore Partners
B5: Methodology | C5: Implied Range ($/sh) | D5: Deal Price ($/sh) | F5: Assessment
B6: DCF — Exit Multiple | C6: ="$"&TEXT('Football Field'!C6,"0.00")&" – $"&TEXT('Football Field'!E6,"0.00") -> $8.84 – $20.97 | D6: ='Football Field'!C10 -> 11.45 | F6: Within Range
B7: DCF — Gordon Growth | C7: ="$"&TEXT('Football Field'!C7,"0.00")&" – $"&TEXT('Football Field'!E7,"0.00") -> $7.98 – $25.29 | D7: ='Football Field'!C10 -> 11.45 | F7: Within Range
B8: Comparable Companies | C8: ="$"&TEXT('Football Field'!C8,"0.00")&" – $"&TEXT('Football Field'!E8,"0.00") -> $10.56 – $26.39 | D8: ='Football Field'!C10 -> 11.45 | F8: Within Range
B9: Precedent Transactions | C9: ="$"&TEXT('Football Field'!C9,"0.00")&" – $"&TEXT('Football Field'!E9,"0.00") -> $12.82 – $35.44 | D9: ='Football Field'!C10 -> 11.45 | F9: Below Range
B11: DEAL STRUCTURE SUMMARY
B12: Cash Consideration | C12: $11.45/share
B13: Contingent Value Right (DAP) | C13: Up to $3.00/share
B14: Total Consideration | C14: Up to $14.45/sh
B15: Implied Deal EV/EBITDA | C15: ~5.1x (cash) / ~5.8x (total)
B16: Sycamore’s Thesis | C16: Control + Restructuring
B17: Financing Condition | C17: Full certainty of close
B19: Sources: Model analysis; WBA press release March 6, 2025; WBA 10-K FY2024; FactSet consensus; precedent transaction SEC filings.
